Workbook

Sheet README
A1: Property Visualisation SaaS — 36-month financial model
A2: Purpose | B2: Test whether a UK-first AI property visualisation SaaS (floor plans / CAD / IFC → geometry-true 3D, renders, tours, video, white-label viewers and configurators) can become a viable business. Built to be conservative: the aim is to find out whether the idea deserves to exist, not to flatter it.
A3: Date / currency | B3: Built 20 Oct 2026. Model currency GBP (£); vendor prices in USD converted at the FX rate below. Prices ex VAT. No corporation tax, VAT timing, R&D credits, capex or working-capital effects (annual prepayments ignored).
A4: FX rate | B4: £0.755 per US$1 (≈ $1.324 per £) — X-Rates October 2026 monthly average (0.755183, 20 days). Editable at Assumptions!D6.
A5: How to use | B5: 1) Change blue cells on Assumptions (and the target-GM row on Pricing, milestone thresholds on Milestones). 2) Everything else recalculates. 3) Read Summary first, then Milestones, Pricing, Unit_Costs. Scenario sheets (Model_Bear / Model_Base / Model_Bull) use Assumptions columns C / D / E respectively. Unit-cost Low/Base/High also use columns C / D / E; each scenario picks a cost case via 'Unit-cost case used'.
A6: Colour legend | B6: Blue text = hard-coded input you can change. Black text = formula. Green text = direct link to another sheet. Yellow-shaded label = ASSUMPTION (modeller's judgement, no source in notes). Light-yellow rows in model sheets = key outputs.
A7: Source labels | B7: VERIFIED = quoted from a vendor or primary page cited in the research notes. ESTIMATE = researcher estimate built from cited prices. ASSUMPTION = modeller's judgement where the notes have no figure (replace with pilot data).
A8: Sheets | B8: Assumptions · Unit_Costs (cost per successful deliverable, Low/Base/High, retry/failure table) · Pricing (tiers, allowances, overage, setup, per-development; GM at included usage; price for 60/70/80/85% GM) · Model_Bear / Model_Base / Model_Bull (monthly, 36m) · Milestones · Summary.
A9: Key modelling choices | B9: MRR milestone metric = subscription MRR only (overage, setup and per-development fees are revenue but not MRR). Customers are expected values (fractional). Hires are step functions triggered by the previous month's customers or MRR. Human QA is costed at contractor rates in COGS even when the founder does it (conservative). Enterprise wins cannot start before month 12 (Base), 18 (Bear), 10 (Bull). Self-serve launch month 6 (Base), 9 (Bear), 4 (Bull).
A10: Research notes | B10: /home/user/widgetme-legal/research_notes/AI property visualisation SaaS audit/ : pricing_inputs.md, market_segments.md, gtm_benchmarks.md, competitors.md, technical_feasibility.md, legal_compliance.md
A12: Sources (from notes)
A13: Claude API pricing (LLM tokens) | B13: https://platform.claude.com/docs/en/about-claude/pricing
A14: Gemini API pricing (Nano Banana images, Veo video) | B14: https://ai.google.dev/gemini-api/docs/pricing
A15: Kling API video pricing | B15: https://kling.ai/document-api/pricing/base/video.md
A16: RunPod GPU pricing | B16: https://www.runpod.io/pricing
A17: AWS g6e.xlarge (Vantage) | B17: https://instances.vantage.sh/aws/ec2/g6e.xlarge
A18: AWS GameLift Streams pricing | B18: https://aws.amazon.com/gamelift/streams/pricing/
A19: Vagon Streams pricing | B19: https://vagon.io/streams/pricing
A20: Cloudflare R2 pricing | B20: https://developers.cloudflare.com/r2/pricing/
A21: Bunny CDN pricing | B21: https://bunny.net/pricing/
A22: Autodesk Flex tokens (APS) | B22: https://www.autodesk.com/buying/flex
A23: APS business model change | B23: https://aps.autodesk.com/blog/aps-business-model-evolution
A24: Upwork rendering freelancer rates | B24: https://www.upwork.com/hire/architectural-rendering-freelancers/cost/
... A47: UK stand sample budget | B47: https://boothexhibits.com/?p=19816

Sheet Assumptions
A1: Assumptions — all model inputs (blue = editable input; black = formula)
A2: Columns C/D/E: for unit-cost inputs = Low / Base / High cost case; for growth inputs = Bear / Base / Bull scenario. Single-value inputs sit in column D. Labels: VERIFIED = quoted from a vendor/primary page in the research notes; ESTIMATE = researcher estimate built from cited prices; ASSUMPTION = modeller's judgement where the notes have no figure.
A4: 1. General
A5: Parameter | B5: Unit | C5: Low / Bear | D5: Base | E5: High / Bull | F5: Label | G5: Source / reasoning
A6: FX rate: GBP per 1 USD | B6: £ per $ | D6: 0.755 | F6: VERIFIED | G6: X-Rates Oct-2026 monthly average 0.755183 (20 days) — https://www.x-rates.com/average/?from=USD&to=GBP&amount=1&year=2026
A7: Starting cash (founder-funded) | B7: £ | D7: 50000 | F7: ASSUMPTION | G7: Brief example: £50k founder-funded. No external funding modelled.
A8: Model horizon | B8: months | D8: 36 | F8: ASSUMPTION | G8: 36 monthly periods; month 1 = first month of company operation (pre-launch build included)
A10: 2. Unit-cost component prices (USD unless stated) — Low / Base / High cost case
A11: Parameter | B11: Unit | C11: Low / Bear | D11: Base | E11: High / Bull | F11: Label | G11: Source / reasoning
A12: LLM floor-plan parse (one high-res plan, structured JSON) | B12: $ / plan | C12: 0.026 | D12: 0.052 | E12: 0.1 | F12: ESTIMATE | G12: pricing_inputs §1: Sonnet 5.5 ≈ $0.052; Batch ≈ $0.026; Opus 5.5 ≈ $0.10 — https://platform.claude.com/docs/en/about-claude/pricing
A13: LLM orchestration + vision QA per generated image | B13: $ / image | C13: 0.02 | D13: 0.03 | E13: 0.05 | F13: ESTIMATE | G13: pricing_inputs §1: $0.02–0.05 per room image on Sonnet 5.5 — https://platform.claude.com/docs/en/about-claude/pricing
A14: LLM shot planning / prompting per video | B14: $ / video | C14: 0.05 | D14: 0.1 | E14: 0.2 | F14: ASSUMPTION | G14: Not in notes; scaled from per-image orchestration cost (a video = ~6 shots).
A15: Image generation per attempt (4K photoreal) | B15: $ / attempt | C15: 0.113 | D15: 0.24 | E15: 0.24 | F15: VERIFIED | G15: Gemini Nano Banana 2.1 4K $0.113 (low); Nano Banana Pro 4K $0.24 (base/high) — https://ai.google.dev/gemini-api/docs/pricing
A16: Generation attempts per accepted image | B16: x | C16: 2 | D16: 3 | E16: 4 | F16: ESTIMATE | G16: pricing_inputs §12: 3 attempts per accepted 4K image (gap: replace with pilot data)
A17: Standard walkthrough video generation | B17: $ / second | C17: 0.07 | D17: 0.12 | E17: 0.168 | F17: VERIFIED | G17: Kling 2.6 1080p $0.07/s; Veo 3.1 Fast 1080p $0.12/s; Kling 3.0 with audio 1080p $0.168/s — https://ai.google.dev/gemini-api/docs/pricing ; https://kling.ai/document-api/pricing/base/video.md
A18: Cinematic video generation | B18: $ / second | C18: 0.12 | D18: 0.4 | E18: 0.6 | F18: VERIFIED | G18: Veo 3.1 Fast $0.12/s (low); Veo 3.1 Std 1080p $0.40/s (base); Veo Std 4K $0.60/s (high) — https://ai.google.dev/gemini-api/docs/pricing
A19: Video retake multiplier (seconds billed / seconds delivered) | B19: x | C19: 1.5 | D19: 2 | E19: 3 | F19: ESTIMATE | G19: pricing_inputs §12: 2x retakes assumed; range is modeller's
A20: Length of standard walkthrough video | B20: seconds | D20: 30 | F20: ASSUMPTION | G20: Deliverable definition (30s walkthrough)
A21: Length of cinematic video | B21: seconds | D21: 60 | F21: ASSUMPTION | G21: Deliverable definition (60s cinematic)
A22: GPU rental for scene build / base render (Blender headless) | B22: $ / GPU-hour | C22: 0.59 | D22: 1.09 | E22: 1.86 | F22: VERIFIED | G22: RunPod L4 $0.59/h; RunPod L40S $1.09/h; AWS g6e.xlarge L40S $1.861/h — https://www.runpod.io/pricing ; https://instances.vantage.sh/aws/ec2/g6e.xlarge
A23: GPU-hours multiplier vs base quantities | B23: x | C23: 0.5 | D23: 1 | E23: 2 | F23: ESTIMATE | G23: pricing_inputs §5: 4K Cycles still 2–10 min on RTX 4090; scene build ~1h L40S. Modelling/asset setup can dominate.
A24: Interactive viewer: pixel-streaming hours per hosted property per month | B24: hours | C24: 0 | D24: 2 | E24: 6.65 | F24: ESTIMATE | G24: pricing_inputs §6: 100 sessions x 8 min = 13.3 h if fully pixel-streamed; high = 50% of sessions streamed (6.65 h). Low = WebGL/three.js only (≈$0). Base = WebGL default + occasional streaming (ASSUMPTION).
A25: Pixel-streaming capacity price | B25: $ / user-hour | C25: 1.82 | D25: 1.82 | E25: 2.82 | F25: VERIFIED | G25: AWS GameLift Streams gen6n_ultra L4 $1.82/h; Vagon L4 Pro G3 $2.82/h — https://aws.amazon.com/gamelift/streams/pricing/ ; https://vagon.io/streams/pricing
A26: Object storage (Cloudflare R2 Standard) | B26: $ / GB-month | D26: 0.015 | F26: VERIFIED | G26: https://developers.cloudflare.com/r2/pricing/
A27: Storage retention charged per deliverable | B27: months | D27: 12 | F27: ASSUMPTION | G27: Assets kept 12 months in hot storage
A28: CDN delivery (Bunny) | B28: $ / GB | C28: 0.005 | D28: 0.01 | E28: 0.01 | F28: VERIFIED | G28: Bunny $0.01/GB EU/NA; $0.005 volume network — https://bunny.net/pricing/
A29: CDN GB per hosted interactive property per month | B29: GB | D29: 10 | F29: ESTIMATE | G29: ~100 WebGL sessions x ~100 MB (modeller's estimate based on pricing_inputs §6 session count)
A30: CAD translation fee (Autodesk APS Flex) per DWG/RVT file | B30: $ / file | C30: 0 | D30: 1.5 | E30: 3 | F30: ESTIMATE | G30: pricing_inputs §8: budget $1.50–$3/file (UNVERIFIED after Dec-2025 APS price change); low = IFC/DXF via open-source parsers — https://www.autodesk.com/buying/flex
A31: Share of plans needing paid CAD translation | B31: % | D31: 0.3 | F31: ASSUMPTION | G31: Most inputs are PDF/raster or IFC/DXF (free parsers); ODA SDK licence covers DWG in-house
A32: Human QA / 2D-confirm operator rate (fully loaded) | B32: $ / hour | C32: 15 | D32: 25 | E32: 35 | F32: ESTIMATE | G32: pricing_inputs §11: offshore $15–25/h (Upwork median $20–30/h; 3D artists $25–40/h); high = $35/h — https://www.upwork.com/hire/architectural-rendering-freelancers/cost/
A33: Human 2D vector/scale confirm-edit per plan | B33: minutes / plan | C33: 3 | D33: 10 | E33: 15 | F33: ESTIMATE | G33: technical_feasibility §7: target 3–5 min clean CAD, 10–15 min scans; pricing_inputs §11: 10–20 min per plan. Mandatory HITL step for raster input — https://tool.planner5d.com/b2b-floor-plan-recognition
A34: Human review per delivered image attempt | B34: minutes / image | C34: 0.5 | D34: 1 | E34: 1.5 | F34: ASSUMPTION | G34: Not measured in notes. Automated drift QA + human spot-check of every customer-facing image (DMCC 2024 misdescription risk).
A35: Human review per video attempt | B35: minutes / video | C35: 5 | D35: 10 | E35: 15 | F35: ASSUMPTION | G35: Watch-through + shot check; not in notes
A36: Human check per development unit (finish swaps / availability data) | B36: minutes / unit | C36: 1 | D36: 1.5 | E36: 2.5 | F36: ASSUMPTION | G36: Not in notes
A37: Customer support handling rate (allocated to COGS) | B37: $ / hour | C37: 25 | D37: 30 | E37: 35 | F37: ASSUMPTION | G37: UK part-time/outsourced support; no UK support salary in notes (gtm_benchmarks gaps)
A38: Support minutes multiplier vs base quantities | B38: x | C38: 0.5 | D38: 1 | E38: 1.5 | F38: ASSUMPTION | G38: Tickets, revision requests, re-uploads
A39: Deliverable-level QA rejection / redo rate used for COGS | B39: % | C39: 0.05 | D39: 0.15 | E39: 0.25 | F39: ASSUMPTION | G39: On top of per-image attempts. Applied as cost per success = fixed + repeatable/(1-f). Replace with pilot data.
A40: Failure-table rate 1 | B40: % | D40: 0.05 | F40: ASSUMPTION | G40: Retry/failure sensitivity table
A41: Failure-table rate 2 | B41: % | D41: 0.15 | F41: ASSUMPTION | G41: Retry/failure sensitivity table
A42: Failure-table rate 3 | B42: % | D42: 0.3 | F42: ASSUMPTION | G42: Retry/failure sensitivity table
...

Sheet Unit_Costs
A1: Unit costs — cost per SUCCESSFUL deliverable, built from components (USD unless stated)
A2: Repeatable components (LLM, image gen, video gen, GPU, output-review QA) are re-incurred when a deliverable is rejected; fixed components (2D confirm, hosting, storage, CDN, CAD fees, support) are incurred once. Cost per success = fixed + repeatable / (1 − failure rate). Human labour (2D confirm + QA + support) is shown explicitly.
A4: LOW cost case
A5: Deliverable | B5: LLM tokens | C5: Image gen | D5: Video gen | E5: GPU render | F5: 3D streaming (1st mo) | G5: Storage | H5: CDN | I5: 3rd-party fees (CAD) | J5: Human 2D confirm | K5: Human output QA | L5: Support alloc. | M5: Attempt cost (USD) | N5: of which repeatable | O5: Failure rate | P5: Cost / success (USD) | Q5: Cost / success (GBP) | R5: Human labour share | S5: Human minutes / success
A6: Single room image | B6: =Assumptions!$B$59*Assumptions!$C$12+Assumptions!$C$59*Assumptions!$C$13+(Assumptions!$D$59+Assumptions!$E$59)*Assumptions!$C$14 -> 0.046 | C6: =Assumptions!$C$59*Assumptions!$C$16*Assumptions!$C$15 -> 0.226 | D6: =(Assumptions!$D$59*Assumptions!$D$20*Assumptions!$C$17+Assumptions!$E$59*Assumptions!$D$21*Assumptions!$C$18)*Assumptions!$C$19 -> 0 | E6: =Assumptions!$F$59*Assumptions!$C$23*Assumptions!$C$22 -> 0.01475 | F6: =Assumptions!$G$59*Assumptions!$C$24*Assumptions!$C$25 -> 0 | G6: =Assumptions!$H$59*Assumptions!$D$26*Assumptions!$D$27 -> 0.018 | H6: =Assumptions!$I$59*Assumptions!$C$28 -> 0.0025 | I6: =Assumptions!$B$59*Assumptions!$D$31*Assumptions!$C$30 -> 0 | J6: =Assumptions!$B$59*Assumptions!$C$33/60*Assumptions!$C$32 -> 0.75 | K6: =(Assumptions!$C$59*Assumptions!$C$34+(Assumptions!$D$59+Assumptions!$E$59)*Assumptions!$C$35+Assumptions!$J$59*Assumptions!$C$36+Assumptions!$K$59)/60*Assumptions!$C$32 -> 0.125 | L6: =Assumptions!$L$59*Assumptions!$C$38/60*Assumptions!$C$37 -> 0.41666667 | M6: =SUM(B6:L6) -> 1.5989167 | N6: =B6+C6+D6+E6+K6 -> 0.41175 | O6: =Assumptions!$C$39 -> 0.05 | P6: =(M6-N6)+N6/(1-O6) -> 1.6205877 | Q6: =P6*Assumptions!$D$6 -> 1.2235437 | R6: =IF(P6=0,0,(J6+K6/(1-O6)+L6)/P6) -> 0.80109555 | S6: =Assumptions!$B$59*Assumptions!$C$33+(Assumptions!$C$59*Assumptions!$C$34+(Assumptions!$D$59+Assumptions!$E$59)*Assumptions!$C$35+Assumptions!$J$59*Assumptions!$C$36+Assumptions!$K$59)/(1-O6)+Assumptions!$L$59*Assumptions!$C$38 -> 4.5263158
A7: 5 room images | B7: =Assumptions!$B$60*Assumptions!$C$12+Assumptions!$C$60*Assumptions!$C$13+(Assumptions!$D$60+Assumptions!$E$60)*Assumptions!$C$14 -> 0.126 | C7: =Assumptions!$C$60*Assumptions!$C$16*Assumptions!$C$15 -> 1.13 | D7: =(Assumptions!$D$60*Assumptions!$D$20*Assumptions!$C$17+Assumptions!$E$60*Assumptions!$D$21*Assumptions!$C$18)*Assumptions!$C$19 -> 0 | E7: =Assumptions!$F$60*Assumptions!$C$23*Assumptions!$C$22 -> 0.059 | F7: =Assumptions!$G$60*Assumptions!$C$24*Assumptions!$C$25 -> 0 | G7: =Assumptions!$H$60*Assumptions!$D$26*Assumptions!$D$27 -> 0.09 | H7: =Assumptions!$I$60*Assumptions!$C$28 -> 0.01 | I7: =Assumptions!$B$60*Assumptions!$D$31*Assumptions!$C$30 -> 0 | J7: =Assumptions!$B$60*Assumptions!$C$33/60*Assumptions!$C$32 -> 0.75 | K7: =(Assumptions!$C$60*Assumptions!$C$34+(Assumptions!$D$60+Assumptions!$E$60)*Assumptions!$C$35+Assumptions!$J$60*Assumptions!$C$36+Assumptions!$K$60)/60*Assumptions!$C$32 -> 1.125 | L7: =Assumptions!$L$60*Assumptions!$C$38/60*Assumptions!$C$37 -> 0.625 | M7: =SUM(B7:L7) -> 3.915 | N7: =B7+C7+D7+E7+K7 -> 2.44 | O7: =Assumptions!$C$39 -> 0.05 | P7: =(M7-N7)+N7/(1-O7) -> 4.0434211 | Q7: =P7*Assumptions!$D$6 -> 3.0527829 | R7: =IF(P7=0,0,(J7+K7/(1-O7)+L7)/P7) -> 0.63293199 | S7: =Assumptions!$B$60*Assumptions!$C$33+(Assumptions!$C$60*Assumptions!$C$34+(Assumptions!$D$60+Assumptions!$E$60)*Assumptions!$C$35+Assumptions!$J$60*Assumptions!$C$36+Assumptions!$K$60)/(1-O7)+Assumptions!$L$60*Assumptions!$C$38 -> 9.2368421
A8: 2-bed flat (8 images + plan) | B8: =Assumptions!$B$61*Assumptions!$C$12+Assumptions!$C$61*Assumptions!$C$13+(Assumptions!$D$61+Assumptions!$E$61)*Assumptions!$C$14 -> 0.186 | C8: =Assumptions!$C$61*Assumptions!$C$16*Assumptions!$C$15 -> 1.808 | D8: =(Assumptions!$D$61*Assumptions!$D$20*Assumptions!$C$17+Assumptions!$E$61*Assumptions!$D$21*Assumptions!$C$18)*Assumptions!$C$19 -> 0 | E8: =Assumptions!$F$61*Assumptions!$C$23*Assumptions!$C$22 -> 0.1475 | F8: =Assumptions!$G$61*Assumptions!$C$24*Assumptions!$C$25 -> 0 | G8: =Assumptions!$H$61*Assumptions!$D$26*Assumptions!$D$27 -> 0.18 | H8: =Assumptions!$I$61*Assumptions!$C$28 -> 0.025 | I8: =Assumptions!$B$61*Assumptions!$D$31*Assumptions!$C$30 -> 0 | J8: =Assumptions!$B$61*Assumptions!$C$33/60*Assumptions!$C$32 -> 0.75 | K8: =(Assumptions!$C$61*Assumptions!$C$34+(Assumptions!$D$61+Assumptions!$E$61)*Assumptions!$C$35+Assumptions!$J$61*Assumptions!$C$36+Assumptions!$K$61)/60*Assumptions!$C$32 -> 2.25 | L8: =Assumptions!$L$61*Assumptions!$C$38/60*Assumptions!$C$37 -> 1.0416667 | M8: =SUM(B8:L8) -> 6.3881667 | N8: =B8+C8+D8+E8+K8 -> 4.3915 | O8: =Assumptions!$C$39 -> 0.05 | P8: =(M8-N8)+N8/(1-O8) -> 6.6192982 | Q8: =P8*Assumptions!$D$6 -> 4.9975702 | R8: =IF(P8=0,0,(J8+K8/(1-O8)+L8)/P8) -> 0.62847866 | S8: =Assumptions!$B$61*Assumptions!$C$33+(Assumptions!$C$61*Assumptions!$C$34+(Assumptions!$D$61+Assumptions!$E$61)*Assumptions!$C$35+Assumptions!$J$61*Assumptions!$C$36+Assumptions!$K$61)/(1-O8)+Assumptions!$L$61*Assumptions!$C$38 -> 14.973684
A9: 4-bed house (19 images, 2 floors) | B9: =Assumptions!$B$62*Assumptions!$C$12+Assumptions!$C$62*Assumptions!$C$13+(Assumptions!$D$62+Assumptions!$E$62)*Assumptions!$C$14 -> 0.432 | C9: =Assumptions!$C$62*Assumptions!$C$16*Assumptions!$C$15 -> 4.294 | D9: =(Assumptions!$D$62*Assumptions!$D$20*Assumptions!$C$17+Assumptions!$E$62*Assumptions!$D$21*Assumptions!$C$18)*Assumptions!$C$19 -> 0 | E9: =Assumptions!$F$62*Assumptions!$C$23*Assumptions!$C$22 -> 0.295 | F9: =Assumptions!$G$62*Assumptions!$C$24*Assumptions!$C$25 -> 0 | G9: =Assumptions!$H$62*Assumptions!$D$26*Assumptions!$D$27 -> 0.36 | H9: =Assumptions!$I$62*Assumptions!$C$28 -> 0.05 | I9: =Assumptions!$B$62*Assumptions!$D$31*Assumptions!$C$30 -> 0 | J9: =Assumptions!$B$62*Assumptions!$C$33/60*Assumptions!$C$32 -> 1.5 | K9: =(Assumptions!$C$62*Assumptions!$C$34+(Assumptions!$D$62+Assumptions!$E$62)*Assumptions!$C$35+Assumptions!$J$62*Assumptions!$C$36+Assumptions!$K$62)/60*Assumptions!$C$32 -> 4.875 | L9: =Assumptions!$L$62*Assumptions!$C$38/60*Assumptions!$C$37 -> 1.6666667 | M9: =SUM(B9:L9) -> 13.472667 | N9: =B9+C9+D9+E9+K9 -> 9.896 | O9: =Assumptions!$C$39 -> 0.05 | P9: =(M9-N9)+N9/(1-O9) -> 13.993509 | Q9: =P9*Assumptions!$D$6 -> 10.565099 | R9: =IF(P9=0,0,(J9+K9/(1-O9)+L9)/P9) -> 0.59300678 | S9: =Assumptions!$B$62*Assumptions!$C$33+(Assumptions!$C$62*Assumptions!$C$34+(Assumptions!$D$62+Assumptions!$E$62)*Assumptions!$C$35+Assumptions!$J$62*Assumptions!$C$36+Assumptions!$K$62)/(1-O9)+Assumptions!$L$62*Assumptions!$C$38 -> 30.526316
A10: Interactive 3D property (WebGL tour, 1st month hosting) | B10: =Assumptions!$B$63*Assumptions!$C$12+Assumptions!$C$63*Assumptions!$C$13+(Assumptions!$D$63+Assumptions!$E$63)*Assumptions!$C$14 -> 0.026 | C10: =Assumptions!$C$63*Assumptions!$C$16*Assumptions!$C$15 -> 0 | D10: =(Assumptions!$D$63*Assumptions!$D$20*Assumptions!$C$17+Assumptions!$E$63*Assumptions!$D$21*Assumptions!$C$18)*Assumptions!$C$19 -> 0 | E10: =Assumptions!$F$63*Assumptions!$C$23*Assumptions!$C$22 -> 0.295 | F10: =Assumptions!$G$63*Assumptions!$C$24*Assumptions!$C$25 -> 0 | G10: =Assumptions!$H$63*Assumptions!$D$26*Assumptions!$D$27 -> 0.36 | H10: =Assumptions!$I$63*Assumptions!$C$28 -> 0.05 | I10: =Assumptions!$B$63*Assumptions!$D$31*Assumptions!$C$30 -> 0 | J10: =Assumptions!$B$63*Assumptions!$C$33/60*Assumptions!$C$32 -> 0.75 | K10: =(Assumptions!$C$63*Assumptions!$C$34+(Assumptions!$D$63+Assumptions!$E$63)*Assumptions!$C$35+Assumptions!$J$63*Assumptions!$C$36+Assumptions!$K$63)/60*Assumptions!$C$32 -> 3.75 | L10: =Assumptions!$L$63*Assumptions!$C$38/60*Assumptions!$C$37 -> 2.0833333 | M10: =SUM(B10:L10) -> 7.3143333 | N10: =B10+C10+D10+E10+K10 -> 4.071 | O10: =Assumptions!$C$39 -> 0.05 | P10: =(M10-N10)+N10/(1-O10) -> 7.5285965 | Q10: =P10*Assumptions!$D$6 -> 5.6840904 | R10: =IF(P10=0,0,(J10+K10/(1-O10)+L10)/P10) -> 0.90065947 | S10: =Assumptions!$B$63*Assumptions!$C$33+(Assumptions!$C$63*Assumptions!$C$34+(Assumptions!$D$63+Assumptions!$E$63)*Assumptions!$C$35+Assumptions!$J$63*Assumptions!$C$36+Assumptions!$K$63)/(1-O10)+Assumptions!$L$63*Assumptions!$C$38 -> 23.789474
A11: 30s walkthrough video | B11: =Assumptions!$B$64*Assumptions!$C$12+Assumptions!$C$64*Assumptions!$C$13+(Assumptions!$D$64+Assumptions!$E$64)*Assumptions!$C$14 -> 0.076 | C11: =Assumptions!$C$64*Assumptions!$C$16*Assumptions!$C$15 -> 0 | D11: =(Assumptions!$D$64*Assumptions!$D$20*Assumptions!$C$17+Assumptions!$E$64*Assumptions!$D$21*Assumptions!$C$18)*Assumptions!$C$19 -> 3.15 | E11: =Assumptions!$F$64*Assumptions!$C$23*Assumptions!$C$22 -> 0.1475 | F11: =Assumptions!$G$64*Assumptions!$C$24*Assumptions!$C$25 -> 0 | G11: =Assumptions!$H$64*Assumptions!$D$26*Assumptions!$D$27 -> 0.09 | H11: =Assumptions!$I$64*Assumptions!$C$28 -> 0.025 | I11: =Assumptions!$B$64*Assumptions!$D$31*Assumptions!$C$30 -> 0 | J11: =Assumptions!$B$64*Assumptions!$C$33/60*Assumptions!$C$32 -> 0.75 | K11: =(Assumptions!$C$64*Assumptions!$C$34+(Assumptions!$D$64+Assumptions!$E$64)*Assumptions!$C$35+Assumptions!$J$64*Assumptions!$C$36+Assumptions!$K$64)/60*Assumptions!$C$32 -> 1.25 | L11: =Assumptions!$L$64*Assumptions!$C$38/60*Assumptions!$C$37 -> 1.0416667 | M11: =SUM(B11:L11) -> 6.5301667 | N11: =B11+C11+D11+E11+K11 -> 4.6235 | O11: =Assumptions!$C$39 -> 0.05 | P11: =(M11-N11)+N11/(1-O11) -> 6.7735088 | Q11: =P11*Assumptions!$D$6 -> 5.1139991 | R11: =IF(P11=0,0,(J11+K11/(1-O11)+L11)/P11) -> 0.45876609 | S11: =Assumptions!$B$64*Assumptions!$C$33+(Assumptions!$C$64*Assumptions!$C$34+(Assumptions!$D$64+Assumptions!$E$64)*Assumptions!$C$35+Assumptions!$J$64*Assumptions!$C$36+Assumptions!$K$64)/(1-O11)+Assumptions!$L$64*Assumptions!$C$38 -> 10.763158
A12: 60s cinematic video | B12: =Assumptions!$B$65*Assumptions!$C$12+Assumptions!$C$65*Assumptions!$C$13+(Assumptions!$D$65+Assumptions!$E$65)*Assumptions!$C$14 -> 0.076 | C12: =Assumptions!$C$65*Assumptions!$C$16*Assumptions!$C$15 -> 0 | D12: =(Assumptions!$D$65*Assumptions!$D$20*Assumptions!$C$17+Assumptions!$E$65*Assumptions!$D$21*Assumptions!$C$18)*Assumptions!$C$19 -> 10.8 | E12: =Assumptions!$F$65*Assumptions!$C$23*Assumptions!$C$22 -> 0.295 | F12: =Assumptions!$G$65*Assumptions!$C$24*Assumptions!$C$25 -> 0 | G12: =Assumptions!$H$65*Assumptions!$D$26*Assumptions!$D$27 -> 0.18 | H12: =Assumptions!$I$65*Assumptions!$C$28 -> 0.05 | I12: =Assumptions!$B$65*Assumptions!$D$31*Assumptions!$C$30 -> 0 | J12: =Assumptions!$B$65*Assumptions!$C$33/60*Assumptions!$C$32 -> 0.75 | K12: =(Assumptions!$C$65*Assumptions!$C$34+(Assumptions!$D$65+Assumptions!$E$65)*Assumptions!$C$35+Assumptions!$J$65*Assumptions!$C$36+Assumptions!$K$65)/60*Assumptions!$C$32 -> 1.25 | L12: =Assumptions!$L$65*Assumptions!$C$38/60*Assumptions!$C$37 -> 1.6666667 | M12: =SUM(B12:L12) -> 15.067667 | N12: =B12+C12+D12+E12+K12 -> 12.421 | O12: =Assumptions!$C$39 -> 0.05 | P12: =(M12-N12)+N12/(1-O12) -> 15.721404 | Q12: =P12*Assumptions!$D$6 -> 11.86966 | R12: =IF(P12=0,0,(J12+K12/(1-O12)+L12)/P12) -> 0.2374124 | S12: =Assumptions!$B$65*Assumptions!$C$33+(Assumptions!$C$65*Assumptions!$C$34+(Assumptions!$D$65+Assumptions!$E$65)*Assumptions!$C$35+Assumptions!$J$65*Assumptions!$C$36+Assumptions!$K$65)/(1-O12)+Assumptions!$L$65*Assumptions!$C$38 -> 12.263158
A13: Developer marketing package (per house type) | B13: =Assumptions!$B$66*Assumptions!$C$12+Assumptions!$C$66*Assumptions!$C$13+(Assumptions!$D$66+Assumptions!$E$66)*Assumptions!$C$14 -> 0.592 | C13: =Assumptions!$C$66*Assumptions!$C$16*Assumptions!$C$15 -> 4.972 | D13: =(Assumptions!$D$66*Assumptions!$D$20*Assumptions!$C$17+Assumptions!$E$66*Assumptions!$D$21*Assumptions!$C$18)*Assumptions!$C$19 -> 13.95 | E13: =Assumptions!$F$66*Assumptions!$C$23*Assumptions!$C$22 -> 0.59 | F13: =Assumptions!$G$66*Assumptions!$C$24*Assumptions!$C$25 -> 0 | G13: =Assumptions!$H$66*Assumptions!$D$26*Assumptions!$D$27 -> 0.54 | H13: =Assumptions!$I$66*Assumptions!$C$28 -> 0.1 | I13: =Assumptions!$B$66*Assumptions!$D$31*Assumptions!$C$30 -> 0 | J13: =Assumptions!$B$66*Assumptions!$C$33/60*Assumptions!$C$32 -> 1.5 | K13: =(Assumptions!$C$66*Assumptions!$C$34+(Assumptions!$D$66+Assumptions!$E$66)*Assumptions!$C$35+Assumptions!$J$66*Assumptions!$C$36+Assumptions!$K$66)/60*Assumptions!$C$32 -> 12.75 | L13: =Assumptions!$L$66*Assumptions!$C$38/60*Assumptions!$C$37 -> 6.25 | M13: =SUM(B13:L13) -> 41.244 | N13: =B13+C13+D13+E13+K13 -> 32.854 | O13: =Assumptions!$C$39 -> 0.05 | P13: =(M13-N13)+N13/(1-O13) -> 42.973158 | Q13: =P13*Assumptions!$D$6 -> 32.444734 | R13: =IF(P13=0,0,(J13+K13/(1-O13)+L13)/P13) -> 0.4926576 | S13: =Assumptions!$B$66*Assumptions!$C$33+(Assumptions!$C$66*Assumptions!$C$34+(Assumptions!$D$66+Assumptions!$E$66)*Assumptions!$C$35+Assumptions!$J$66*Assumptions!$C$36+Assumptions!$K$66)/(1-O13)+Assumptions!$L$66*Assumptions!$C$38 -> 74.684211
A14: 50-unit development (6 plan types) | B14: =Assumptions!$B$67*Assumptions!$C$12+Assumptions!$C$67*Assumptions!$C$13+(Assumptions!$D$67+Assumptions!$E$67)*Assumptions!$C$14 -> 6.552 | C14: =Assumptions!$C$67*Assumptions!$C$16*Assumptions!$C$15 -> 63.732 | D14: =(Assumptions!$D$67*Assumptions!$D$20*Assumptions!$C$17+Assumptions!$E$67*Assumptions!$D$21*Assumptions!$C$18)*Assumptions!$C$19 -> 83.7 | E14: =Assumptions!$F$67*Assumptions!$C$23*Assumptions!$C$22 -> 4.13 | F14: =Assumptions!$G$67*Assumptions!$C$24*Assumptions!$C$25 -> 0 | G14: =Assumptions!$H$67*Assumptions!$D$26*Assumptions!$D$27 -> 4.14 | H14: =Assumptions!$I$67*Assumptions!$C$28 -> 0.85 | I14: =Assumptions!$B$67*Assumptions!$D$31*Assumptions!$C$30 -> 0 | J14: =Assumptions!$B$67*Assumptions!$C$33/60*Assumptions!$C$32 -> 9 | K14: =(Assumptions!$C$67*Assumptions!$C$34+(Assumptions!$D$67+Assumptions!$E$67)*Assumptions!$C$35+Assumptions!$J$67*Assumptions!$C$36+Assumptions!$K$67)/60*Assumptions!$C$32 -> 122.75 | L14: =Assumptions!$L$67*Assumptions!$C$38/60*Assumptions!$C$37 -> 25 | M14: =SUM(B14:L14) -> 319.854 | N14: =B14+C14+D14+E14+K14 -> 280.864 | O14: =Assumptions!$C$39 -> 0.05 | P14: =(M14-N14)+N14/(1-O14) -> 334.63632 | Q14: =P14*Assumptions!$D$6 -> 252.65042 | R14: =IF(P14=0,0,(J14+K14/(1-O14)+L14)/P14) -> 0.48772509 | S14: =Assumptions!$B$67*Assumptions!$C$33+(Assumptions!$C$67*Assumptions!$C$34+(Assumptions!$D$67+Assumptions!$E$67)*Assumptions!$C$35+Assumptions!$J$67*Assumptions!$C$36+Assumptions!$K$67)/(1-O14)+Assumptions!$L$67*Assumptions!$C$38 -> 612.84211
A15: 200-unit development (15 plan types) | B15: =Assumptions!$B$68*Assumptions!$C$12+Assumptions!$C$68*Assumptions!$C$13+(Assumptions!$D$68+Assumptions!$E$68)*Assumptions!$C$14 -> 20.88 | C15: =Assumptions!$C$68*Assumptions!$C$16*Assumptions!$C$15 -> 210.18 | D15: =(Assumptions!$D$68*Assumptions!$D$20*Assumptions!$C$17+Assumptions!$E$68*Assumptions!$D$21*Assumptions!$C$18)*Assumptions!$C$19 -> 209.25 | E15: =Assumptions!$F$68*Assumptions!$C$23*Assumptions!$C$22 -> 9.44 | F15: =Assumptions!$G$68*Assumptions!$C$24*Assumptions!$C$25 -> 0 | G15: =Assumptions!$H$68*Assumptions!$D$26*Assumptions!$D$27 -> 11.7 | H15: =Assumptions!$I$68*Assumptions!$C$28 -> 2.5 | I15: =Assumptions!$B$68*Assumptions!$D$31*Assumptions!$C$30 -> 0 | J15: =Assumptions!$B$68*Assumptions!$C$33/60*Assumptions!$C$32 -> 22.5 | K15: =(Assumptions!$C$68*Assumptions!$C$34+(Assumptions!$D$68+Assumptions!$E$68)*Assumptions!$C$35+Assumptions!$J$68*Assumptions!$C$36+Assumptions!$K$68)/60*Assumptions!$C$32 -> 331.25 | L15: =Assumptions!$L$68*Assumptions!$C$38/60*Assumptions!$C$37 -> 50 | M15: =SUM(B15:L15) -> 867.7 | N15: =B15+C15+D15+E15+K15 -> 781 | O15: =Assumptions!$C$39 -> 0.05 | P15: =(M15-N15)+N15/(1-O15) -> 908.80526 | Q15: =P15*Assumptions!$D$6 -> 686.14797 | R15: =IF(P15=0,0,(J15+K15/(1-O15)+L15)/P15) -> 0.46344825 | S15: =Assumptions!$B$68*Assumptions!$C$33+(Assumptions!$C$68*Assumptions!$C$34+(Assumptions!$D$68+Assumptions!$E$68)*Assumptions!$C$35+Assumptions!$J$68*Assumptions!$C$36+Assumptions!$K$68)/(1-O15)+Assumptions!$L$68*Assumptions!$C$38 -> 1604.7368
A16: Ongoing hosting per interactive property per month (streaming + CDN + storage) | M16: =Assumptions!$C$24*Assumptions!$C$25+Assumptions!$D$29*Assumptions!$C$28+Assumptions!$D$44*Assumptions!$D$26 -> 0.08 | Q16: =M16*Assumptions!$D$6 -> 0.0604
A18: BASE cost case
A19: Deliverable | B19: LLM tokens | C19: Image gen | D19: Video gen | E19: GPU render | F19: 3D streaming (1st mo) | G19: Storage | H19: CDN | I19: 3rd-party fees (CAD) | J19: Human 2D confirm | K19: Human output QA | L19: Support alloc. | M19: Attempt cost (USD) | N19: of which repeatable | O19: Failure rate | P19: Cost / success (USD) | Q19: Cost / success (GBP) | R19: Human labour share | S19: Human minutes / success
A20: Single room image | B20: =Assumptions!$B$59*Assumptions!$D$12+Assumptions!$C$59*Assumptions!$D$13+(Assumptions!$D$59+Assumptions!$E$59)*Assumptions!$D$14 -> 0.082 | C20: =Assumptions!$C$59*Assumptions!$D$16*Assumptions!$D$15 -> 0.72 | D20: =(Assumptions!$D$59*Assumptions!$D$20*Assumptions!$D$17+Assumptions!$E$59*Assumptions!$D$21*Assumptions!$D$18)*Assumptions!$D$19 -> 0 | E20: =Assumptions!$F$59*Assumptions!$D$23*Assumptions!$D$22 -> 0.0545 | F20: =Assumptions!$G$59*Assumptions!$D$24*Assumptions!$D$25 -> 0 | G20: =Assumptions!$H$59*Assumptions!$D$26*Assumptions!$D$27 -> 0.018 | H20: =Assumptions!$I$59*Assumptions!$D$28 -> 0.005 | I20: =Assumptions!$B$59*Assumptions!$D$31*Assumptions!$D$30 -> 0.45 | J20: =Assumptions!$B$59*Assumptions!$D$33/60*Assumptions!$D$32 -> 4.1666667 | K20: =(Assumptions!$C$59*Assumptions!$D$34+(Assumptions!$D$59+Assumptions!$E$59)*Assumptions!$D$35+Assumptions!$J$59*Assumptions!$D$36+Assumptions!$K$59)/60*Assumptions!$D$32 -> 0.41666667 | L20: =Assumptions!$L$59*Assumptions!$D$38/60*Assumptions!$D$37 -> 1 | M20: =SUM(B20:L20) -> 6.9128333 | N20: =B20+C20+D20+E20+K20 -> 1.2731667 | O20: =Assumptions!$D$39 -> 0.15 | P20: =(M20-N20)+N20/(1-O20) -> 7.1375098 | Q20: =P20*Assumptions!$D$6 -> 5.3888199 | R20: =IF(P20=0,0,(J20+K20/(1-O20)+L20)/P20) -> 0.79255411 | S20: =Assumptions!$B$59*Assumptions!$D$33+(Assumptions!$C$59*Assumptions!$D$34+(Assumptions!$D$59+Assumptions!$E$59)*Assumptions!$D$35+Assumptions!$J$59*Assumptions!$D$36+Assumptions!$K$59)/(1-O20)+Assumptions!$L$59*Assumptions!$D$38 -> 13.176471
A21: 5 room images | B21: =Assumptions!$B$60*Assumptions!$D$12+Assumptions!$C$60*Assumptions!$D$13+(Assumptions!$D$60+Assumptions!$E$60)*Assumptions!$D$14 -> 0.202 | C21: =Assumptions!$C$60*Assumptions!$D$16*Assumptions!$D$15 -> 3.6 | D21: =(Assumptions!$D$60*Assumptions!$D$20*Assumptions!$D$17+Assumptions!$E$60*Assumptions!$D$21*Assumptions!$D$18)*Assumptions!$D$19 -> 0 | E21: =Assumptions!$F$60*Assumptions!$D$23*Assumptions!$D$22 -> 0.218 | F21: =Assumptions!$G$60*Assumptions!$D$24*Assumptions!$D$25 -> 0 | G21: =Assumptions!$H$60*Assumptions!$D$26*Assumptions!$D$27 -> 0.09 | H21: =Assumptions!$I$60*Assumptions!$D$28 -> 0.02 | I21: =Assumptions!$B$60*Assumptions!$D$31*Assumptions!$D$30 -> 0.45 | J21: =Assumptions!$B$60*Assumptions!$D$33/60*Assumptions!$D$32 -> 4.1666667 | K21: =(Assumptions!$C$60*Assumptions!$D$34+(Assumptions!$D$60+Assumptions!$E$60)*Assumptions!$D$35+Assumptions!$J$60*Assumptions!$D$36+Assumptions!$K$60)/60*Assumptions!$D$32 -> 2.9166667 | L21: =Assumptions!$L$60*Assumptions!$D$38/60*Assumptions!$D$37 -> 1.5 | M21: =SUM(B21:L21) -> 13.163333 | N21: =B21+C21+D21+E21+K21 -> 6.9366667 | O21: =Assumptions!$D$39 -> 0.15 | P21: =(M21-N21)+N21/(1-O21) -> 14.387451 | Q21: =P21*Assumptions!$D$6 -> 10.862525 | R21: =IF(P21=0,0,(J21+K21/(1-O21)+L21)/P21) -> 0.63235935 | S21: =Assumptions!$B$60*Assumptions!$D$33+(Assumptions!$C$60*Assumptions!$D$34+(Assumptions!$D$60+Assumptions!$E$60)*Assumptions!$D$35+Assumptions!$J$60*Assumptions!$D$36+Assumptions!$K$60)/(1-O21)+Assumptions!$L$60*Assumptions!$D$38 -> 21.235294
A22: 2-bed flat (8 images + plan) | B22: =Assumptions!$B$61*Assumptions!$D$12+Assumptions!$C$61*Assumptions!$D$13+(Assumptions!$D$61+Assumptions!$E$61)*Assumptions!$D$14 -> 0.292 | C22: =Assumptions!$C$61*Assumptions!$D$16*Assumptions!$D$15 -> 5.76 | D22: =(Assumptions!$D$61*Assumptions!$D$20*Assumptions!$D$17+Assumptions!$E$61*Assumptions!$D$21*Assumptions!$D$18)*Assumptions!$D$19 -> 0 | E22: =Assumptions!$F$61*Assumptions!$D$23*Assumptions!$D$22 -> 0.545 | F22: =Assumptions!$G$61*Assumptions!$D$24*Assumptions!$D$25 -> 0 | G22: =Assumptions!$H$61*Assumptions!$D$26*Assumptions!$D$27 -> 0.18 | H22: =Assumptions!$I$61*Assumptions!$D$28 -> 0.05 | I22: =Assumptions!$B$61*Assumptions!$D$31*Assumptions!$D$30 -> 0.45 | J22: =Assumptions!$B$61*Assumptions!$D$33/60*Assumptions!$D$32 -> 4.1666667 | K22: =(Assumptions!$C$61*Assumptions!$D$34+(Assumptions!$D$61+Assumptions!$E$61)*Assumptions!$D$35+Assumptions!$J$61*Assumptions!$D$36+Assumptions!$K$61)/60*Assumptions!$D$32 -> 5.4166667 | L22: =Assumptions!$L$61*Assumptions!$D$38/60*Assumptions!$D$37 -> 2.5 | M22: =SUM(B22:L22) -> 19.360333 | N22: =B22+C22+D22+E22+K22 -> 12.013667 | O22: =Assumptions!$D$39 -> 0.15 | P22: =(M22-N22)+N22/(1-O22) -> 21.480392 | Q22: =P22*Assumptions!$D$6 -> 16.217696 | R22: =IF(P22=0,0,(J22+K22/(1-O22)+L22)/P22) -> 0.60702875 | S22: =Assumptions!$B$61*Assumptions!$D$33+(Assumptions!$C$61*Assumptions!$D$34+(Assumptions!$D$61+Assumptions!$E$61)*Assumptions!$D$35+Assumptions!$J$61*Assumptions!$D$36+Assumptions!$K$61)/(1-O22)+Assumptions!$L$61*Assumptions!$D$38 -> 30.294118
A23: 4-bed house (19 images, 2 floors) | B23: =Assumptions!$B$62*Assumptions!$D$12+Assumptions!$C$62*Assumptions!$D$13+(Assumptions!$D$62+Assumptions!$E$62)*Assumptions!$D$14 -> 0.674 | C23: =Assumptions!$C$62*Assumptions!$D$16*Assumptions!$D$15 -> 13.68 | D23: =(Assumptions!$D$62*Assumptions!$D$20*Assumptions!$D$17+Assumptions!$E$62*Assumptions!$D$21*Assumptions!$D$18)*Assumptions!$D$19 -> 0 | E23: =Assumptions!$F$62*Assumptions!$D$23*Assumptions!$D$22 -> 1.09 | F23: =Assumptions!$G$62*Assumptions!$D$24*Assumptions!$D$25 -> 0 | G23: =Assumptions!$H$62*Assumptions!$D$26*Assumptions!$D$27 -> 0.36 | H23: =Assumptions!$I$62*Assumptions!$D$28 -> 0.1 | I23: =Assumptions!$B$62*Assumptions!$D$31*Assumptions!$D$30 -> 0.9 | J23: =Assumptions!$B$62*Assumptions!$D$33/60*Assumptions!$D$32 -> 8.3333333 | K23: =(Assumptions!$C$62*Assumptions!$D$34+(Assumptions!$D$62+Assumptions!$E$62)*Assumptions!$D$35+Assumptions!$J$62*Assumptions!$D$36+Assumptions!$K$62)/60*Assumptions!$D$32 -> 12.083333 | L23: =Assumptions!$L$62*Assumptions!$D$38/60*Assumptions!$D$37 -> 4 | M23: =SUM(B23:L23) -> 41.220667 | N23: =B23+C23+D23+E23+K23 -> 27.527333 | O23: =Assumptions!$D$39 -> 0.15 | P23: =(M23-N23)+N23/(1-O23) -> 46.078431 | Q23: =P23*Assumptions!$D$6 -> 34.789216 | R23: =IF(P23=0,0,(J23+K23/(1-O23)+L23)/P23) -> 0.57617021 | S23: =Assumptions!$B$62*Assumptions!$D$33+(Assumptions!$C$62*Assumptions!$D$34+(Assumptions!$D$62+Assumptions!$E$62)*Assumptions!$D$35+Assumptions!$J$62*Assumptions!$D$36+Assumptions!$K$62)/(1-O23)+Assumptions!$L$62*Assumptions!$D$38 -> 62.117647
A24: Interactive 3D property (WebGL tour, 1st month hosting) | B24: =Assumptions!$B$63*Assumptions!$D$12+Assumptions!$C$63*Assumptions!$D$13+(Assumptions!$D$63+Assumptions!$E$63)*Assumptions!$D$14 -> 0.052 | C24: =Assumptions!$C$63*Assumptions!$D$16*Assumptions!$D$15 -> 0 | D24: =(Assumptions!$D$63*Assumptions!$D$20*Assumptions!$D$17+Assumptions!$E$63*Assumptions!$D$21*Assumptions!$D$18)*Assumptions!$D$19 -> 0 | E24: =Assumptions!$F$63*Assumptions!$D$23*Assumptions!$D$22 -> 1.09 | F24: =Assumptions!$G$63*Assumptions!$D$24*Assumptions!$D$25 -> 3.64 | G24: =Assumptions!$H$63*Assumptions!$D$26*Assumptions!$D$27 -> 0.36 | H24: =Assumptions!$I$63*Assumptions!$D$28 -> 0.1 | I24: =Assumptions!$B$63*Assumptions!$D$31*Assumptions!$D$30 -> 0.45 | J24: =Assumptions!$B$63*Assumptions!$D$33/60*Assumptions!$D$32 -> 4.1666667 | K24: =(Assumptions!$C$63*Assumptions!$D$34+(Assumptions!$D$63+Assumptions!$E$63)*Assumptions!$D$35+Assumptions!$J$63*Assumptions!$D$36+Assumptions!$K$63)/60*Assumptions!$D$32 -> 6.25 | L24: =Assumptions!$L$63*Assumptions!$D$38/60*Assumptions!$D$37 -> 5 | M24: =SUM(B24:L24) -> 21.108667 | N24: =B24+C24+D24+E24+K24 -> 7.392 | O24: =Assumptions!$D$39 -> 0.15 | P24: =(M24-N24)+N24/(1-O24) -> 22.413137 | Q24: =P24*Assumptions!$D$6 -> 16.921919 | R24: =IF(P24=0,0,(J24+K24/(1-O24)+L24)/P24) -> 0.73705022 | S24: =Assumptions!$B$63*Assumptions!$D$33+(Assumptions!$C$63*Assumptions!$D$34+(Assumptions!$D$63+Assumptions!$E$63)*Assumptions!$D$35+Assumptions!$J$63*Assumptions!$D$36+Assumptions!$K$63)/(1-O24)+Assumptions!$L$63*Assumptions!$D$38 -> 37.647059
A25: 30s walkthrough video | B25: =Assumptions!$B$64*Assumptions!$D$12+Assumptions!$C$64*Assumptions!$D$13+(Assumptions!$D$64+Assumptions!$E$64)*Assumptions!$D$14 -> 0.152 | C25: =Assumptions!$C$64*Assumptions!$D$16*Assumptions!$D$15 -> 0 | D25: =(Assumptions!$D$64*Assumptions!$D$20*Assumptions!$D$17+Assumptions!$E$64*Assumptions!$D$21*Assumptions!$D$18)*Assumptions!$D$19 -> 7.2 | E25: =Assumptions!$F$64*Assumptions!$D$23*Assumptions!$D$22 -> 0.545 | F25: =Assumptions!$G$64*Assumptions!$D$24*Assumptions!$D$25 -> 0 | G25: =Assumptions!$H$64*Assumptions!$D$26*Assumptions!$D$27 -> 0.09 | H25: =Assumptions!$I$64*Assumptions!$D$28 -> 0.05 | I25: =Assumptions!$B$64*Assumptions!$D$31*Assumptions!$D$30 -> 0.45 | J25: =Assumptions!$B$64*Assumptions!$D$33/60*Assumptions!$D$32 -> 4.1666667 | K25: =(Assumptions!$C$64*Assumptions!$D$34+(Assumptions!$D$64+Assumptions!$E$64)*Assumptions!$D$35+Assumptions!$J$64*Assumptions!$D$36+Assumptions!$K$64)/60*Assumptions!$D$32 -> 4.1666667 | L25: =Assumptions!$L$64*Assumptions!$D$38/60*Assumptions!$D$37 -> 2.5 | M25: =SUM(B25:L25) -> 19.320333 | N25: =B25+C25+D25+E25+K25 -> 12.063667 | O25: =Assumptions!$D$39 -> 0.15 | P25: =(M25-N25)+N25/(1-O25) -> 21.449216 | Q25: =P25*Assumptions!$D$6 -> 16.194158 | R25: =IF(P25=0,0,(J25+K25/(1-O25)+L25)/P25) -> 0.53934967 | S25: =Assumptions!$B$64*Assumptions!$D$33+(Assumptions!$C$64*Assumptions!$D$34+(Assumptions!$D$64+Assumptions!$E$64)*Assumptions!$D$35+Assumptions!$J$64*Assumptions!$D$36+Assumptions!$K$64)/(1-O25)+Assumptions!$L$64*Assumptions!$D$38 -> 26.764706
A26: 60s cinematic video | B26: =Assumptions!$B$65*Assumptions!$D$12+Assumptions!$C$65*Assumptions!$D$13+(Assumptions!$D$65+Assumptions!$E$65)*Assumptions!$D$14 -> 0.152 | C26: =Assumptions!$C$65*Assumptions!$D$16*Assumptions!$D$15 -> 0 | D26: =(Assumptions!$D$65*Assumptions!$D$20*Assumptions!$D$17+Assumptions!$E$65*Assumptions!$D$21*Assumptions!$D$18)*Assumptions!$D$19 -> 48 | E26: =Assumptions!$F$65*Assumptions!$D$23*Assumptions!$D$22 -> 1.09 | F26: =Assumptions!$G$65*Assumptions!$D$24*Assumptions!$D$25 -> 0 | G26: =Assumptions!$H$65*Assumptions!$D$26*Assumptions!$D$27 -> 0.18 | H26: =Assumptions!$I$65*Assumptions!$D$28 -> 0.1 | I26: =Assumptions!$B$65*Assumptions!$D$31*Assumptions!$D$30 -> 0.45 | J26: =Assumptions!$B$65*Assumptions!$D$33/60*Assumptions!$D$32 -> 4.1666667 | K26: =(Assumptions!$C$65*Assumptions!$D$34+(Assumptions!$D$65+Assumptions!$E$65)*Assumptions!$D$35+Assumptions!$J$65*Assumptions!$D$36+Assumptions!$K$65)/60*Assumptions!$D$32 -> 4.1666667 | L26: =Assumptions!$L$65*Assumptions!$D$38/60*Assumptions!$D$37 -> 4 | M26: =SUM(B26:L26) -> 62.305333 | N26: =B26+C26+D26+E26+K26 -> 53.408667 | O26: =Assumptions!$D$39 -> 0.15 | P26: =(M26-N26)+N26/(1-O26) -> 71.730392 | Q26: =P26*Assumptions!$D$6 -> 54.156446 | R26: =IF(P26=0,0,(J26+K26/(1-O26)+L26)/P26) -> 0.18219094 | S26: =Assumptions!$B$65*Assumptions!$D$33+(Assumptions!$C$65*Assumptions!$D$34+(Assumptions!$D$65+Assumptions!$E$65)*Assumptions!$D$35+Assumptions!$J$65*Assumptions!$D$36+Assumptions!$K$65)/(1-O26)+Assumptions!$L$65*Assumptions!$D$38 -> 29.764706
A27: Developer marketing package (per house type) | B27: =Assumptions!$B$66*Assumptions!$D$12+Assumptions!$C$66*Assumptions!$D$13+(Assumptions!$D$66+Assumptions!$E$66)*Assumptions!$D$14 -> 0.964 | C27: =Assumptions!$C$66*Assumptions!$D$16*Assumptions!$D$15 -> 15.84 | D27: =(Assumptions!$D$66*Assumptions!$D$20*Assumptions!$D$17+Assumptions!$E$66*Assumptions!$D$21*Assumptions!$D$18)*Assumptions!$D$19 -> 55.2 | E27: =Assumptions!$F$66*Assumptions!$D$23*Assumptions!$D$22 -> 2.18 | F27: =Assumptions!$G$66*Assumptions!$D$24*Assumptions!$D$25 -> 3.64 | G27: =Assumptions!$H$66*Assumptions!$D$26*Assumptions!$D$27 -> 0.54 | H27: =Assumptions!$I$66*Assumptions!$D$28 -> 0.2 | I27: =Assumptions!$B$66*Assumptions!$D$31*Assumptions!$D$30 -> 0.9 | J27: =Assumptions!$B$66*Assumptions!$D$33/60*Assumptions!$D$32 -> 8.3333333 | K27: =(Assumptions!$C$66*Assumptions!$D$34+(Assumptions!$D$66+Assumptions!$E$66)*Assumptions!$D$35+Assumptions!$J$66*Assumptions!$D$36+Assumptions!$K$66)/60*Assumptions!$D$32 -> 30 | L27: =Assumptions!$L$66*Assumptions!$D$38/60*Assumptions!$D$37 -> 15 | M27: =SUM(B27:L27) -> 132.79733 | N27: =B27+C27+D27+E27+K27 -> 104.184 | O27: =Assumptions!$D$39 -> 0.15 | P27: =(M27-N27)+N27/(1-O27) -> 151.18275 | Q27: =P27*Assumptions!$D$6 -> 114.14297 | R27: =IF(P27=0,0,(J27+K27/(1-O27)+L27)/P27) -> 0.38779195 | S27: =Assumptions!$B$66*Assumptions!$D$33+(Assumptions!$C$66*Assumptions!$D$34+(Assumptions!$D$66+Assumptions!$E$66)*Assumptions!$D$35+Assumptions!$J$66*Assumptions!$D$36+Assumptions!$K$66)/(1-O27)+Assumptions!$L$66*Assumptions!$D$38 -> 134.70588
A28: 50-unit development (6 plan types) | B28: =Assumptions!$B$67*Assumptions!$D$12+Assumptions!$C$67*Assumptions!$D$13+(Assumptions!$D$67+Assumptions!$E$67)*Assumptions!$D$14 -> 10.284 | C28: =Assumptions!$C$67*Assumptions!$D$16*Assumptions!$D$15 -> 203.04 | D28: =(Assumptions!$D$67*Assumptions!$D$20*Assumptions!$D$17+Assumptions!$E$67*Assumptions!$D$21*Assumptions!$D$18)*Assumptions!$D$19 -> 331.2 | E28: =Assumptions!$F$67*Assumptions!$D$23*Assumptions!$D$22 -> 15.26 | F28: =Assumptions!$G$67*Assumptions!$D$24*Assumptions!$D$25 -> 21.84 | G28: =Assumptions!$H$67*Assumptions!$D$26*Assumptions!$D$27 -> 4.14 | H28: =Assumptions!$I$67*Assumptions!$D$28 -> 1.7 | I28: =Assumptions!$B$67*Assumptions!$D$31*Assumptions!$D$30 -> 5.4 | J28: =Assumptions!$B$67*Assumptions!$D$33/60*Assumptions!$D$32 -> 50 | K28: =(Assumptions!$C$67*Assumptions!$D$34+(Assumptions!$D$67+Assumptions!$E$67)*Assumptions!$D$35+Assumptions!$J$67*Assumptions!$D$36+Assumptions!$K$67)/60*Assumptions!$D$32 -> 298.75 | L28: =Assumptions!$L$67*Assumptions!$D$38/60*Assumptions!$D$37 -> 60 | M28: =SUM(B28:L28) -> 1001.614 | N28: =B28+C28+D28+E28+K28 -> 858.534 | O28: =Assumptions!$D$39 -> 0.15 | P28: =(M28-N28)+N28/(1-O28) -> 1153.12 | Q28: =P28*Assumptions!$D$6 -> 870.6056 | R28: =IF(P28=0,0,(J28+K28/(1-O28)+L28)/P28) -> 0.40019303 | S28: =Assumptions!$B$67*Assumptions!$D$33+(Assumptions!$C$67*Assumptions!$D$34+(Assumptions!$D$67+Assumptions!$E$67)*Assumptions!$D$35+Assumptions!$J$67*Assumptions!$D$36+Assumptions!$K$67)/(1-O28)+Assumptions!$L$67*Assumptions!$D$38 -> 1083.5294
A29: 200-unit development (15 plan types) | B29: =Assumptions!$B$68*Assumptions!$D$12+Assumptions!$C$68*Assumptions!$D$13+(Assumptions!$D$68+Assumptions!$E$68)*Assumptions!$D$14 -> 32.46 | C29: =Assumptions!$C$68*Assumptions!$D$16*Assumptions!$D$15 -> 669.6 | D29: =(Assumptions!$D$68*Assumptions!$D$20*Assumptions!$D$17+Assumptions!$E$68*Assumptions!$D$21*Assumptions!$D$18)*Assumptions!$D$19 -> 828 | E29: =Assumptions!$F$68*Assumptions!$D$23*Assumptions!$D$22 -> 34.88 | F29: =Assumptions!$G$68*Assumptions!$D$24*Assumptions!$D$25 -> 54.6 | G29: =Assumptions!$H$68*Assumptions!$D$26*Assumptions!$D$27 -> 11.7 | H29: =Assumptions!$I$68*Assumptions!$D$28 -> 5 | I29: =Assumptions!$B$68*Assumptions!$D$31*Assumptions!$D$30 -> 13.5 | J29: =Assumptions!$B$68*Assumptions!$D$33/60*Assumptions!$D$32 -> 125 | K29: =(Assumptions!$C$68*Assumptions!$D$34+(Assumptions!$D$68+Assumptions!$E$68)*Assumptions!$D$35+Assumptions!$J$68*Assumptions!$D$36+Assumptions!$K$68)/60*Assumptions!$D$32 -> 850 | L29: =Assumptions!$L$68*Assumptions!$D$38/60*Assumptions!$D$37 -> 120 | M29: =SUM(B29:L29) -> 2744.74 | N29: =B29+C29+D29+E29+K29 -> 2414.94 | O29: =Assumptions!$D$39 -> 0.15 | P29: =(M29-N29)+N29/(1-O29) -> 3170.9059 | Q29: =P29*Assumptions!$D$6 -> 2394.0339 | R29: =IF(P29=0,0,(J29+K29/(1-O29)+L29)/P29) -> 0.39263228 | S29: =Assumptions!$B$68*Assumptions!$D$33+(Assumptions!$C$68*Assumptions!$D$34+(Assumptions!$D$68+Assumptions!$E$68)*Assumptions!$D$35+Assumptions!$J$68*Assumptions!$D$36+Assumptions!$K$68)/(1-O29)+Assumptions!$L$68*Assumptions!$D$38 -> 2940
A30: Ongoing hosting per interactive property per month (streaming + CDN + storage) | M30: =Assumptions!$D$24*Assumptions!$D$25+Assumptions!$D$29*Assumptions!$D$28+Assumptions!$D$44*Assumptions!$D$26 -> 3.77 | Q30: =M30*Assumptions!$D$6 -> 2.84635
A32: HIGH cost case
A33: Deliverable | B33: LLM tokens | C33: Image gen | D33: Video gen | E33: GPU render | F33: 3D streaming (1st mo) | G33: Storage | H33: CDN | I33: 3rd-party fees (CAD) | J33: Human 2D confirm | K33: Human output QA | L33: Support alloc. | M33: Attempt cost (USD) | N33: of which repeatable | O33: Failure rate | P33: Cost / success (USD) | Q33: Cost / success (GBP) | R33: Human labour share | S33: Human minutes / success
A34: Single room image | B34: =Assumptions!$B$59*Assumptions!$E$12+Assumptions!$C$59*Assumptions!$E$13+(Assumptions!$D$59+Assumptions!$E$59)*Assumptions!$E$14 -> 0.15 | C34: =Assumptions!$C$59*Assumptions!$E$16*Assumptions!$E$15 -> 0.96 | D34: =(Assumptions!$D$59*Assumptions!$D$20*Assumptions!$E$17+Assumptions!$E$59*Assumptions!$D$21*Assumptions!$E$18)*Assumptions!$E$19 -> 0 | E34: =Assumptions!$F$59*Assumptions!$E$23*Assumptions!$E$22 -> 0.186 | F34: =Assumptions!$G$59*Assumptions!$E$24*Assumptions!$E$25 -> 0 | G34: =Assumptions!$H$59*Assumptions!$D$26*Assumptions!$D$27 -> 0.018 | H34: =Assumptions!$I$59*Assumptions!$E$28 -> 0.005 | I34: =Assumptions!$B$59*Assumptions!$D$31*Assumptions!$E$30 -> 0.9 | J34: =Assumptions!$B$59*Assumptions!$E$33/60*Assumptions!$E$32 -> 8.75 | K34: =(Assumptions!$C$59*Assumptions!$E$34+(Assumptions!$D$59+Assumptions!$E$59)*Assumptions!$E$35+Assumptions!$J$59*Assumptions!$E$36+Assumptions!$K$59)/60*Assumptions!$E$32 -> 0.875 | L34: =Assumptions!$L$59*Assumptions!$E$38/60*Assumptions!$E$37 -> 1.75 | M34: =SUM(B34:L34) -> 13.594 | N34: =B34+C34+D34+E34+K34 -> 2.171 | O34: =Assumptions!$E$39 -> 0.25 | P34: =(M34-N34)+N34/(1-O34) -> 14.317667 | Q34: =P34*Assumptions!$D$6 -> 10.809838 | R34: =IF(P34=0,0,(J34+K34/(1-O34)+L34)/P34) -> 0.81484413 | S34: =Assumptions!$B$59*Assumptions!$E$33+(Assumptions!$C$59*Assumptions!$E$34+(Assumptions!$D$59+Assumptions!$E$59)*Assumptions!$E$35+Assumptions!$J$59*Assumptions!$E$36+Assumptions!$K$59)/(1-O34)+Assumptions!$L$59*Assumptions!$E$38 -> 20
A35: 5 room images | B35: =Assumptions!$B$60*Assumptions!$E$12+Assumptions!$C$60*Assumptions!$E$13+(Assumptions!$D$60+Assumptions!$E$60)*Assumptions!$E$14 -> 0.35 | C35: =Assumptions!$C$60*Assumptions!$E$16*Assumptions!$E$15 -> 4.8 | D35: =(Assumptions!$D$60*Assumptions!$D$20*Assumptions!$E$17+Assumptions!$E$60*Assumptions!$D$21*Assumptions!$E$18)*Assumptions!$E$19 -> 0 | E35: =Assumptions!$F$60*Assumptions!$E$23*Assumptions!$E$22 -> 0.744 | F35: =Assumptions!$G$60*Assumptions!$E$24*Assumptions!$E$25 -> 0 | G35: =Assumptions!$H$60*Assumptions!$D$26*Assumptions!$D$27 -> 0.09 | H35: =Assumptions!$I$60*Assumptions!$E$28 -> 0.02 | I35: =Assumptions!$B$60*Assumptions!$D$31*Assumptions!$E$30 -> 0.9 | J35: =Assumptions!$B$60*Assumptions!$E$33/60*Assumptions!$E$32 -> 8.75 | K35: =(Assumptions!$C$60*Assumptions!$E$34+(Assumptions!$D$60+Assumptions!$E$60)*Assumptions!$E$35+Assumptions!$J$60*Assumptions!$E$36+Assumptions!$K$60)/60*Assumptions!$E$32 -> 5.5416667 | L35: =Assumptions!$L$60*Assumptions!$E$38/60*Assumptions!$E$37 -> 2.625 | M35: =SUM(B35:L35) -> 23.820667 | N35: =B35+C35+D35+E35+K35 -> 11.435667 | O35: =Assumptions!$E$39 -> 0.25 | P35: =(M35-N35)+N35/(1-O35) -> 27.632556 | Q35: =P35*Assumptions!$D$6 -> 20.862579 | R35: =IF(P35=0,0,(J35+K35/(1-O35)+L35)/P35) -> 0.67905007 | S35: =Assumptions!$B$60*Assumptions!$E$33+(Assumptions!$C$60*Assumptions!$E$34+(Assumptions!$D$60+Assumptions!$E$60)*Assumptions!$E$35+Assumptions!$J$60*Assumptions!$E$36+Assumptions!$K$60)/(1-O35)+Assumptions!$L$60*Assumptions!$E$38 -> 32.166667
A36: 2-bed flat (8 images + plan) | B36: =Assumptions!$B$61*Assumptions!$E$12+Assumptions!$C$61*Assumptions!$E$13+(Assumptions!$D$61+Assumptions!$E$61)*Assumptions!$E$14 -> 0.5 | C36: =Assumptions!$C$61*Assumptions!$E$16*Assumptions!$E$15 -> 7.68 | D36: =(Assumptions!$D$61*Assumptions!$D$20*Assumptions!$E$17+Assumptions!$E$61*Assumptions!$D$21*Assumptions!$E$18)*Assumptions!$E$19 -> 0 | E36: =Assumptions!$F$61*Assumptions!$E$23*Assumptions!$E$22 -> 1.86 | F36: =Assumptions!$G$61*Assumptions!$E$24*Assumptions!$E$25 -> 0 | G36: =Assumptions!$H$61*Assumptions!$D$26*Assumptions!$D$27 -> 0.18 | H36: =Assumptions!$I$61*Assumptions!$E$28 -> 0.05 | I36: =Assumptions!$B$61*Assumptions!$D$31*Assumptions!$E$30 -> 0.9 | J36: =Assumptions!$B$61*Assumptions!$E$33/60*Assumptions!$E$32 -> 8.75 | K36: =(Assumptions!$C$61*Assumptions!$E$34+(Assumptions!$D$61+Assumptions!$E$61)*Assumptions!$E$35+Assumptions!$J$61*Assumptions!$E$36+Assumptions!$K$61)/60*Assumptions!$E$32 -> 9.9166667 | L36: =Assumptions!$L$61*Assumptions!$E$38/60*Assumptions!$E$37 -> 4.375 | M36: =SUM(B36:L36) -> 34.211667 | N36: =B36+C36+D36+E36+K36 -> 19.956667 | O36: =Assumptions!$E$39 -> 0.25 | P36: =(M36-N36)+N36/(1-O36) -> 40.863889 | Q36: =P36*Assumptions!$D$6 -> 30.852236 | R36: =IF(P36=0,0,(J36+K36/(1-O36)+L36)/P36) -> 0.64475563 | S36: =Assumptions!$B$61*Assumptions!$E$33+(Assumptions!$C$61*Assumptions!$E$34+(Assumptions!$D$61+Assumptions!$E$61)*Assumptions!$E$35+Assumptions!$J$61*Assumptions!$E$36+Assumptions!$K$61)/(1-O36)+Assumptions!$L$61*Assumptions!$E$38 -> 45.166667
A37: 4-bed house (19 images, 2 floors) | B37: =Assumptions!$B$62*Assumptions!$E$12+Assumptions!$C$62*Assumptions!$E$13+(Assumptions!$D$62+Assumptions!$E$62)*Assumptions!$E$14 -> 1.15 | C37: =Assumptions!$C$62*Assumptions!$E$16*Assumptions!$E$15 -> 18.24 | D37: =(Assumptions!$D$62*Assumptions!$D$20*Assumptions!$E$17+Assumptions!$E$62*Assumptions!$D$21*Assumptions!$E$18)*Assumptions!$E$19 -> 0 | E37: =Assumptions!$F$62*Assumptions!$E$23*Assumptions!$E$22 -> 3.72 | F37: =Assumptions!$G$62*Assumptions!$E$24*Assumptions!$E$25 -> 0 | G37: =Assumptions!$H$62*Assumptions!$D$26*Assumptions!$D$27 -> 0.36 | H37: =Assumptions!$I$62*Assumptions!$E$28 -> 0.1 | I37: =Assumptions!$B$62*Assumptions!$D$31*Assumptions!$E$30 -> 1.8 | J37: =Assumptions!$B$62*Assumptions!$E$33/60*Assumptions!$E$32 -> 17.5 | K37: =(Assumptions!$C$62*Assumptions!$E$34+(Assumptions!$D$62+Assumptions!$E$62)*Assumptions!$E$35+Assumptions!$J$62*Assumptions!$E$36+Assumptions!$K$62)/60*Assumptions!$E$32 -> 22.458333 | L37: =Assumptions!$L$62*Assumptions!$E$38/60*Assumptions!$E$37 -> 7 | M37: =SUM(B37:L37) -> 72.328333 | N37: =B37+C37+D37+E37+K37 -> 45.568333 | O37: =Assumptions!$E$39 -> 0.25 | P37: =(M37-N37)+N37/(1-O37) -> 87.517778 | Q37: =P37*Assumptions!$D$6 -> 66.075922 | R37: =IF(P37=0,0,(J37+K37/(1-O37)+L37)/P37) -> 0.62209583 | S37: =Assumptions!$B$62*Assumptions!$E$33+(Assumptions!$C$62*Assumptions!$E$34+(Assumptions!$D$62+Assumptions!$E$62)*Assumptions!$E$35+Assumptions!$J$62*Assumptions!$E$36+Assumptions!$K$62)/(1-O37)+Assumptions!$L$62*Assumptions!$E$38 -> 93.333333
A38: Interactive 3D property (WebGL tour, 1st month hosting) | B38: =Assumptions!$B$63*Assumptions!$E$12+Assumptions!$C$63*Assumptions!$E$13+(Assumptions!$D$63+Assumptions!$E$63)*Assumptions!$E$14 -> 0.1 | C38: =Assumptions!$C$63*Assumptions!$E$16*Assumptions!$E$15 -> 0 | D38: =(Assumptions!$D$63*Assumptions!$D$20*Assumptions!$E$17+Assumptions!$E$63*Assumptions!$D$21*Assumptions!$E$18)*Assumptions!$E$19 -> 0 | E38: =Assumptions!$F$63*Assumptions!$E$23*Assumptions!$E$22 -> 3.72 | F38: =Assumptions!$G$63*Assumptions!$E$24*Assumptions!$E$25 -> 18.753 | G38: =Assumptions!$H$63*Assumptions!$D$26*Assumptions!$D$27 -> 0.36 | H38: =Assumptions!$I$63*Assumptions!$E$28 -> 0.1 | I38: =Assumptions!$B$63*Assumptions!$D$31*Assumptions!$E$30 -> 0.9 | J38: =Assumptions!$B$63*Assumptions!$E$33/60*Assumptions!$E$32 -> 8.75 | K38: =(Assumptions!$C$63*Assumptions!$E$34+(Assumptions!$D$63+Assumptions!$E$63)*Assumptions!$E$35+Assumptions!$J$63*Assumptions!$E$36+Assumptions!$K$63)/60*Assumptions!$E$32 -> 8.75 | L38: =Assumptions!$L$63*Assumptions!$E$38/60*Assumptions!$E$37 -> 8.75 | M38: =SUM(B38:L38) -> 50.183 | N38: =B38+C38+D38+E38+K38 -> 12.57 | O38: =Assumptions!$E$39 -> 0.25 | P38: =(M38-N38)+N38/(1-O38) -> 54.373 | Q38: =P38*Assumptions!$D$6 -> 41.051615 | R38: =IF(P38=0,0,(J38+K38/(1-O38)+L38)/P38) -> 0.5364182 | S38: =Assumptions!$B$63*Assumptions!$E$33+(Assumptions!$C$63*Assumptions!$E$34+(Assumptions!$D$63+Assumptions!$E$63)*Assumptions!$E$35+Assumptions!$J$63*Assumptions!$E$36+Assumptions!$K$63)/(1-O38)+Assumptions!$L$63*Assumptions!$E$38 -> 50
A39: 30s walkthrough video | B39: =Assumptions!$B$64*Assumptions!$E$12+Assumptions!$C$64*Assumptions!$E$13+(Assumptions!$D$64+Assumptions!$E$64)*Assumptions!$E$14 -> 0.3 | C39: =Assumptions!$C$64*Assumptions!$E$16*Assumptions!$E$15 -> 0 | D39: =(Assumptions!$D$64*Assumptions!$D$20*Assumptions!$E$17+Assumptions!$E$64*Assumptions!$D$21*Assumptions!$E$18)*Assumptions!$E$19 -> 15.12 | E39: =Assumptions!$F$64*Assumptions!$E$23*Assumptions!$E$22 -> 1.86 | F39: =Assumptions!$G$64*Assumptions!$E$24*Assumptions!$E$25 -> 0 | G39: =Assumptions!$H$64*Assumptions!$D$26*Assumptions!$D$27 -> 0.09 | H39: =Assumptions!$I$64*Assumptions!$E$28 -> 0.05 | I39: =Assumptions!$B$64*Assumptions!$D$31*Assumptions!$E$30 -> 0.9 | J39: =Assumptions!$B$64*Assumptions!$E$33/60*Assumptions!$E$32 -> 8.75 | K39: =(Assumptions!$C$64*Assumptions!$E$34+(Assumptions!$D$64+Assumptions!$E$64)*Assumptions!$E$35+Assumptions!$J$64*Assumptions!$E$36+Assumptions!$K$64)/60*Assumptions!$E$32 -> 8.75 | L39: =Assumptions!$L$64*Assumptions!$E$38/60*Assumptions!$E$37 -> 4.375 | M39: =SUM(B39:L39) -> 40.195 | N39: =B39+C39+D39+E39+K39 -> 26.03 | O39: =Assumptions!$E$39 -> 0.25 | P39: =(M39-N39)+N39/(1-O39) -> 48.871667 | Q39: =P39*Assumptions!$D$6 -> 36.898108 | R39: =IF(P39=0,0,(J39+K39/(1-O39)+L39)/P39) -> 0.50728097 | S39: =Assumptions!$B$64*Assumptions!$E$33+(Assumptions!$C$64*Assumptions!$E$34+(Assumptions!$D$64+Assumptions!$E$64)*Assumptions!$E$35+Assumptions!$J$64*Assumptions!$E$36+Assumptions!$K$64)/(1-O39)+Assumptions!$L$64*Assumptions!$E$38 -> 42.5
A40: 60s cinematic video | B40: =Assumptions!$B$65*Assumptions!$E$12+Assumptions!$C$65*Assumptions!$E$13+(Assumptions!$D$65+Assumptions!$E$65)*Assumptions!$E$14 -> 0.3 | C40: =Assumptions!$C$65*Assumptions!$E$16*Assumptions!$E$15 -> 0 | D40: =(Assumptions!$D$65*Assumptions!$D$20*Assumptions!$E$17+Assumptions!$E$65*Assumptions!$D$21*Assumptions!$E$18)*Assumptions!$E$19 -> 108 | E40: =Assumptions!$F$65*Assumptions!$E$23*Assumptions!$E$22 -> 3.72 | F40: =Assumptions!$G$65*Assumptions!$E$24*Assumptions!$E$25 -> 0 | G40: =Assumptions!$H$65*Assumptions!$D$26*Assumptions!$D$27 -> 0.18 | H40: =Assumptions!$I$65*Assumptions!$E$28 -> 0.1 | I40: =Assumptions!$B$65*Assumptions!$D$31*Assumptions!$E$30 -> 0.9 | J40: =Assumptions!$B$65*Assumptions!$E$33/60*Assumptions!$E$32 -> 8.75 | K40: =(Assumptions!$C$65*Assumptions!$E$34+(Assumptions!$D$65+Assumptions!$E$65)*Assumptions!$E$35+Assumptions!$J$65*Assumptions!$E$36+Assumptions!$K$65)/60*Assumptions!$E$32 -> 8.75 | L40: =Assumptions!$L$65*Assumptions!$E$38/60*Assumptions!$E$37 -> 7 | M40: =SUM(B40:L40) -> 137.7 | N40: =B40+C40+D40+E40+K40 -> 120.77 | O40: =Assumptions!$E$39 -> 0.25 | P40: =(M40-N40)+N40/(1-O40) -> 177.95667 | Q40: =P40*Assumptions!$D$6 -> 134.35728 | R40: =IF(P40=0,0,(J40+K40/(1-O40)+L40)/P40) -> 0.15406372 | S40: =Assumptions!$B$65*Assumptions!$E$33+(Assumptions!$C$65*Assumptions!$E$34+(Assumptions!$D$65+Assumptions!$E$65)*Assumptions!$E$35+Assumptions!$J$65*Assumptions!$E$36+Assumptions!$K$65)/(1-O40)+Assumptions!$L$65*Assumptions!$E$38 -> 47
A41: Developer marketing package (per house type) | B41: =Assumptions!$B$66*Assumptions!$E$12+Assumptions!$C$66*Assumptions!$E$13+(Assumptions!$D$66+Assumptions!$E$66)*Assumptions!$E$14 -> 1.7 | C41: =Assumptions!$C$66*Assumptions!$E$16*Assumptions!$E$15 -> 21.12 | D41: =(Assumptions!$D$66*Assumptions!$D$20*Assumptions!$E$17+Assumptions!$E$66*Assumptions!$D$21*Assumptions!$E$18)*Assumptions!$E$19 -> 123.12 | E41: =Assumptions!$F$66*Assumptions!$E$23*Assumptions!$E$22 -> 7.44 | F41: =Assumptions!$G$66*Assumptions!$E$24*Assumptions!$E$25 -> 18.753 | G41: =Assumptions!$H$66*Assumptions!$D$26*Assumptions!$D$27 -> 0.54 | H41: =Assumptions!$I$66*Assumptions!$E$28 -> 0.2 | I41: =Assumptions!$B$66*Assumptions!$D$31*Assumptions!$E$30 -> 1.8 | J41: =Assumptions!$B$66*Assumptions!$E$33/60*Assumptions!$E$32 -> 17.5 | K41: =(Assumptions!$C$66*Assumptions!$E$34+(Assumptions!$D$66+Assumptions!$E$66)*Assumptions!$E$35+Assumptions!$J$66*Assumptions!$E$36+Assumptions!$K$66)/60*Assumptions!$E$32 -> 54.25 | L41: =Assumptions!$L$66*Assumptions!$E$38/60*Assumptions!$E$37 -> 26.25 | M41: =SUM(B41:L41) -> 272.673 | N41: =B41+C41+D41+E41+K41 -> 207.63 | O41: =Assumptions!$E$39 -> 0.25 | P41: =(M41-N41)+N41/(1-O41) -> 341.883 | Q41: =P41*Assumptions!$D$6 -> 258.12167 | R41: =IF(P41=0,0,(J41+K41/(1-O41)+L41)/P41) -> 0.33954111 | S41: =Assumptions!$B$66*Assumptions!$E$33+(Assumptions!$C$66*Assumptions!$E$34+(Assumptions!$D$66+Assumptions!$E$66)*Assumptions!$E$35+Assumptions!$J$66*Assumptions!$E$36+Assumptions!$K$66)/(1-O41)+Assumptions!$L$66*Assumptions!$E$38 -> 199
A42: 50-unit development (6 plan types) | B42: =Assumptions!$B$67*Assumptions!$E$12+Assumptions!$C$67*Assumptions!$E$13+(Assumptions!$D$67+Assumptions!$E$67)*Assumptions!$E$14 -> 17.7 | C42: =Assumptions!$C$67*Assumptions!$E$16*Assumptions!$E$15 -> 270.72 | D42: =(Assumptions!$D$67*Assumptions!$D$20*Assumptions!$E$17+Assumptions!$E$67*Assumptions!$D$21*Assumptions!$E$18)*Assumptions!$E$19 -> 738.72 | E42: =Assumptions!$F$67*Assumptions!$E$23*Assumptions!$E$22 -> 52.08 | F42: =Assumptions!$G$67*Assumptions!$E$24*Assumptions!$E$25 -> 112.518 | G42: =Assumptions!$H$67*Assumptions!$D$26*Assumptions!$D$27 -> 4.14 | H42: =Assumptions!$I$67*Assumptions!$E$28 -> 1.7 | I42: =Assumptions!$B$67*Assumptions!$D$31*Assumptions!$E$30 -> 10.8 | J42: =Assumptions!$B$67*Assumptions!$E$33/60*Assumptions!$E$32 -> 105 | K42: =(Assumptions!$C$67*Assumptions!$E$34+(Assumptions!$D$67+Assumptions!$E$67)*Assumptions!$E$35+Assumptions!$J$67*Assumptions!$E$36+Assumptions!$K$67)/60*Assumptions!$E$32 -> 564.66667 | L42: =Assumptions!$L$67*Assumptions!$E$38/60*Assumptions!$E$37 -> 105 | M42: =SUM(B42:L42) -> 1983.0447 | N42: =B42+C42+D42+E42+K42 -> 1643.8867 | O42: =Assumptions!$E$39 -> 0.25 | P42: =(M42-N42)+N42/(1-O42) -> 2531.0069 | Q42: =P42*Assumptions!$D$6 -> 1910.9102 | R42: =IF(P42=0,0,(J42+K42/(1-O42)+L42)/P42) -> 0.38043709 | S42: =Assumptions!$B$67*Assumptions!$E$33+(Assumptions!$C$67*Assumptions!$E$34+(Assumptions!$D$67+Assumptions!$E$67)*Assumptions!$E$35+Assumptions!$J$67*Assumptions!$E$36+Assumptions!$K$67)/(1-O42)+Assumptions!$L$67*Assumptions!$E$38 -> 1650.6667
